<?xml version="1.0"?>
<robot name="robot">

  <link name="base_link">
    <visual>
      <geometry>
        <cylinder length="0.2" radius="1.0" />
      </geometry>
      <material name="orange" >
        <color rgba="1.0 0.65 0 1.0" />
      </material>
    </visual>
  </link>
 
  <link name="upper_base_link">
    <visual>
      <geometry>
        <cylinder length="0.6" radius="0.8" />
      </geometry>
        <origin rpy="0 0 0" xyz="0 0 0.4" />
      <material name="orange" />
    </visual>
  </link>

  <joint name="base_to_upper_base_joint" type="fixed">
    <parent link="base_link" />
    <child link="upper_base_link" />
  </joint>

  <link name="top_base_link">
    <visual>
      <geometry>
        <cylinder length="0.2" radius="0.8" />
      </geometry>
      <material name="green" >
      <color rgba="0 0.8 0 1.0" />
      </material>
       <origin rpy="0 0 0" xyz="0 0 0.6" />
    </visual>
  </link>

   <joint name="upper_to_top_base_joint" type="continuous">
    <parent link="upper_base_link" />
    <child link="top_base_link" />
    <axis xyz="0 0 1" />
    <origin rpy="0 0 0" xyz="0 0 0" />
  </joint> 

  <link name="blue_cyl_link">
    <visual>
      <geometry>
        <cylinder length="0.2" radius="0.2" />
      </geometry>
        <origin rpy="0 0 0" xyz="0 0 0" />
        <material name="blue" >
        <color rgba="0 0.2 0.8 1" />
        </material>
    </visual>
  </link>

   <joint name="top_to_blue_joint" type="revolute">
    <axis xyz="0 0 1" />
    <origin rpy="1.57079 0 1.57079" xyz="0 0.15 0.9" />
    <limit effort="1000.0" lower="-1.570796" upper="1.570796" velocity="0.5" />
    <parent link="top_base_link" />
    <child link="blue_cyl_link" />
  </joint> 

  <link name="blue_box_link">
    <visual>
      <geometry>
        <box size="0.2 2.0 0.2" />
      </geometry>
        <origin rpy="0 0 0" xyz="0 1.0 0" />
        <material name="blue" />
    </visual>
  </link>

   <joint name="blue_cyl_to_box_joint" type="fixed">
    <origin rpy="0 0 -0.7854" xyz="0 0 0" />
    <parent link="blue_cyl_link" />
    <child link="blue_box_link" />
  </joint> 

  <link name="brown_cyl_link">
    <visual>
      <geometry>
        <cylinder length="0.2" radius="0.15" />
      </geometry>
        <origin rpy="0 0 0" xyz="0 0 0" />
        <material name="brown" >
        <color rgba="0.55 0.271 0.075 1.0" />
        </material>
    </visual>
  </link>

   <joint name="box_to_brown_cyl_joint" type="revolute">
    <axis xyz="0 0 1" />
    <origin rpy="0 0 1.57079" xyz="0 2.0 0" />
    <limit effort="1000.0" lower="-1.570796" upper="1.570796" velocity="0.5" />
    <parent link="blue_box_link" />
    <child link="brown_cyl_link" />
  </joint> 


  <link name="brown_tri_link">
    <visual>
      <geometry>
        <box size="0.2 0.2 0.2" />
      </geometry>
        <origin rpy="0 0 0" xyz="0 0 0" />
        <material name="brown" />
    </visual>
  </link>

   <joint name="brown_cyl_to_tri_joint" type="fixed">
    <origin rpy="0 0 0" xyz="0.2 0 0" />
    <parent link="brown_cyl_link" />
    <child link="brown_tri_link" />
  </joint> 

  <link name="yellow_cyl_link">
    <visual>
      <geometry>
        <cylinder length="3.0" radius="0.075" />
      </geometry>
        <origin rpy="0 0 0" xyz="0 0 0.5" />
        <material name="yellow" >
        <color rgba="1 1 0.0 1.0" />
        </material>
      </visual>
  </link>

   <joint name="tri_to_cyl_joint" type="continuous">
    <parent link="brown_tri_link" />
    <child link="yellow_cyl_link" />
    <axis xyz="0 0 1" />
    <origin rpy="1.57079 0 0.7854" xyz="0 0 0" />
  </joint> 


  <link name="brown_hand_link">
    <visual>
      <geometry>
        <cylinder length="0.2" radius="0.125" />
      </geometry>
        <origin rpy="0 0 0" xyz="0 0 0" />
        <material name="brown" />
    </visual>
  </link>

   <joint name="cyl_to_hand_joint" type="revolute">
    <parent link="yellow_cyl_link" />
    <child link="brown_hand_link" />
    <limit effort="1000.0" lower="-1.570796" upper="1.570796" velocity="0.5" />
    <axis xyz="0 0 1" />
    <origin rpy="-1.57079 0 0" xyz="0 0 2" />
  </joint> 

  <link name="light_purple_hand_link">
    <visual>
      <geometry>
        <cylinder length="0.3" radius="0.05" />
      </geometry>
        <origin rpy="0 0 0" xyz="0 0 .15" />
        <material name="purple" >
        <color rgba="0.5 0 0.5 1.0" />
        </material>
    </visual>
  </link>

   <joint name="brown_to_purple_joint" type="continuous">
    <parent link="brown_hand_link" />
    <child link="light_purple_hand_link" />
    <axis xyz="0 0 1" />
    <origin rpy="0.7854 1.57079 -1.57079" xyz="0 0 0" />
  </joint> 

  <link name="dark_purple_hand_link">
    <visual>
      <geometry>
        <cylinder length="0.05" radius="0.1" />
      </geometry>
        <material name="purple" />
        <origin rpy="0 0 0" xyz="0 0 -0.025" />
    </visual>
  </link>

   <joint name="light_dark_purple_joint" type="fixed">
    <origin rpy="0 0 0" xyz="0 0 0.3025" />
    <parent link="light_purple_hand_link" />
    <child link="dark_purple_hand_link" />
  </joint> 



</robot>
